2020-06-01 15:30:29,758-ERROR-loger.py-46-autotest_log-日志信息:发起get请求报错！错误是HTTPConnectionPool(host='web.panda-inner.co', port=80): Max retries exceeded with url: /api/user/checkIntroUser?introUser= (Caused by NewConnectionError('<urllib3.connection.HTTPConnection object at 0x04097EB0>: Failed to establish a new connection: [Errno 11004] getaddrinfo failed',))
